Traceback (most recent call last):
  File "C:\Users\faalc\AppData\Local\pypoetry\Cache\virtualenvs\healthcare-regression-jPCn2AX--py3.11\Lib\site-packages\nbclient\client.py", line 782, in _async_poll_for_reply
    msg = await ensure_async(self.kc.shell_channel.get_msg(timeout=new_timeout))
          ^^^^^^^^^^^^^^^^^^^^^^^^^^^^^^^^^^^^^^^^^^^^^^^^^^^^^^^^^^^^^^^^^^^^^^
  File "C:\Users\faalc\AppData\Local\pypoetry\Cache\virtualenvs\healthcare-regression-jPCn2AX--py3.11\Lib\site-packages\jupyter_core\utils\__init__.py", line 198, in ensure_async
    result = await obj
             ^^^^^^^^^
  File "C:\Users\faalc\AppData\Local\pypoetry\Cache\virtualenvs\healthcare-regression-jPCn2AX--py3.11\Lib\site-packages\jupyter_client\channels.py", line 313, in get_msg
    raise Empty
_queue.Empty

During handling of the above exception, another exception occurred:

Traceback (most recent call last):
  File "C:\Users\faalc\AppData\Local\pypoetry\Cache\virtualenvs\healthcare-regression-jPCn2AX--py3.11\Lib\site-packages\jupyter_cache\executors\utils.py", line 58, in single_nb_execution
    executenb(
  File "C:\Users\faalc\AppData\Local\pypoetry\Cache\virtualenvs\healthcare-regression-jPCn2AX--py3.11\Lib\site-packages\nbclient\client.py", line 1314, in execute
    return NotebookClient(nb=nb, resources=resources, km=km, **kwargs).execute()
           ^^^^^^^^^^^^^^^^^^^^^^^^^^^^^^^^^^^^^^^^^^^^^^^^^^^^^^^^^^^^^^^^^^^^^
  File "C:\Users\faalc\AppData\Local\pypoetry\Cache\virtualenvs\healthcare-regression-jPCn2AX--py3.11\Lib\site-packages\jupyter_core\utils\__init__.py", line 165, in wrapped
    return loop.run_until_complete(inner)
           ^^^^^^^^^^^^^^^^^^^^^^^^^^^^^^
  File "C:\Users\faalc\AppData\Local\Programs\Python\Python311\Lib\asyncio\base_events.py", line 650, in run_until_complete
    return future.result()
           ^^^^^^^^^^^^^^^
  File "C:\Users\faalc\AppData\Local\Programs\Python\Python311\Lib\contextlib.py", line 222, in __aexit__
    await self.gen.athrow(typ, value, traceback)
  File "C:\Users\faalc\AppData\Local\pypoetry\Cache\virtualenvs\healthcare-regression-jPCn2AX--py3.11\Lib\site-packages\nbclient\client.py", line 654, in async_setup_kernel
    yield
  File "C:\Users\faalc\AppData\Local\pypoetry\Cache\virtualenvs\healthcare-regression-jPCn2AX--py3.11\Lib\site-packages\nbclient\client.py", line 709, in async_execute
    await self.async_execute_cell(
  File "C:\Users\faalc\AppData\Local\pypoetry\Cache\virtualenvs\healthcare-regression-jPCn2AX--py3.11\Lib\site-packages\nbclient\client.py", line 1005, in async_execute_cell
    exec_reply = await self.task_poll_for_reply
                 ^^^^^^^^^^^^^^^^^^^^^^^^^^^^^^
  File "C:\Users\faalc\AppData\Local\pypoetry\Cache\virtualenvs\healthcare-regression-jPCn2AX--py3.11\Lib\site-packages\nbclient\client.py", line 806, in _async_poll_for_reply
    error_on_timeout_execute_reply = await self._async_handle_timeout(timeout, cell)
                                     ^^^^^^^^^^^^^^^^^^^^^^^^^^^^^^^^^^^^^^^^^^^^^^^
  File "C:\Users\faalc\AppData\Local\pypoetry\Cache\virtualenvs\healthcare-regression-jPCn2AX--py3.11\Lib\site-packages\nbclient\client.py", line 856, in _async_handle_timeout
    raise CellTimeoutError.error_from_timeout_and_cell(
nbclient.exceptions.CellTimeoutError: A cell timed out while it was being executed, after 30 seconds.
The message was: Cell execution timed out.
Here is a preview of the cell contents:
-------------------
['param_grid = {', '    "max_depth": [None, 2, 5, 7],', '    "min_samples_split": [2, 4, 6, 8, 10],', '    "min_samples_leaf": [1, 2, 4, 6, 8]', '}']
...
['model = RandomForestRegressor(n_jobs=-1)', '', 'grid_search = GridSearchCV(model, param_grid=param_grid, cv=5) ', '', 'grid_search.fit(X_train, y_train)']
-------------------

